public class ExceptionHandlingDemo {
    public static void main(String[] args) {
        try {
            int result = divide(10, 0);
            System.out.println("Result of division: " + result); 
        } catch (ArithmeticException e) {
            System.out.println("Caught ArithmeticException: " + e.getMessage());
        }

        try {
            // Accessing an invalid index - ArrayIndexOutOfBoundsException
            int[] arr = {1, 2, 3};
            System.out.println("Value at index 3: " + arr[3]);
        } catch (ArrayIndexOutOfBoundsException e) {
            System.out.println("Caught ArrayIndexOutOfBoundsException: " + e.getMessage());
        } finally {
            System.out.println("Finally block executed.");
        }

        try {
            validateAge(15); 
            System.out.println("Age is valid."); 
        } catch (CustomException e) {
            System.out.println("Caught CustomException: " + e.getMessage());
        }
    }

    public static int divide(int num1, int num2) {
        return num1 / num2;
    }

    public static void validateAge(int age) throws CustomException {
        if (age < 18) {
            throw new CustomException("Age must be 18 or above.");
        }
    }
}

class CustomException extends Exception {
    public CustomException(String message) {
        super(message);
    }
}
